Workbook

Sheet README
B2: Statistical Analysis on MPG — Excel Edition
B4: This workbook reproduces, using native Excel formulas, the same six hypothesis tests that were originally performed in Python (pandas + scipy.stats) in '5_statistical_analysis_MPG.ipynb'. Every number below is a live formula — change the raw data on the 'Data' tab and every test recalculates automatically.
B7: Assumption: the dataset (398 vehicles, same as the notebook) has been exported to a CSV and uploaded / pasted into the 'Data' tab, exactly as you would upload a CSV into pandas with pd.read_csv(). Missing 'horsepower' values were mean-imputed, matching the cleaned pickle used in the notebook.
B10: How this workbook is organised
B12: Sheet | C12: Test | D12: Python (scipy.stats) | E12: Excel function(s)
B13: Data | C13: Raw dataset (from CSV) | D13: pd.read_pickle / read_csv | E13: —
B14: 1-Sample T-Test | C14: Is mean MPG different from 25? | D14: scipy.stats.ttest_1samp | E14: AVERAGE, STDEV.S, T.DIST.2T
B15: 2-Sample T-Test | C15: USA vs Japan mean MPG | D15: scipy.stats.ttest_ind(equal_var=False) | E15: T.TEST(...,2,3)
B16: 1-Way ANOVA | C16: MPG across USA / Japan / Europe | D16: scipy.stats.f_oneway | E16: DEVSQ, F.DIST.RT
B17: Correlation | C17: Weight vs MPG relationship | D17: scipy.stats.pearsonr | E17: CORREL, T.DIST.2T
B18: Variance Test | C18: USA vs Japan MPG variance | D18: scipy.stats.levene | E18: F.TEST (F-test analogue)
B19: Newer vs Older | C19: Are post-1975 cars more efficient? | D19: scipy.stats.ttest_ind (one-sided) | E19: T.TEST(...,1,3)
B21: Colour legend
B23: Input | C23: Yellow cells = editable assumptions (α, hypothesised mean μ₀, etc.)
B24: =1+1 -> 2 | C24: Green cells = key results (test statistic, p-value)
B25: Decision | C25: Orange cells = the Reject/Fail-to-reject conclusion

Sheet Data
A1: Raw data as uploaded from CSV (this is the CSV export of the cleaned MPG dataset — equivalent to df = pd.read_csv('mpg_data.csv') in the notebook). 398 vehicles, no missing values (horsepower nulls were mean-imputed before export).
A2: mpg | B2: cylinders | C2: displacement | D2: horsepower | E2: weight | F2: acceleration | G2: model_year | H2: origin | I2: name
A3: 18 | B3: 8 | C3: 307 | D3: 130 | E3: 3504 | F3: 12 | G3: 70 | H3: usa | I3: chevrolet chevelle malibu
A4: 15 | B4: 8 | C4: 350 | D4: 165 | E4: 3693 | F4: 11.5 | G4: 70 | H4: usa | I4: buick skylark 320
A5: 18 | B5: 8 | C5: 318 | D5: 150 | E5: 3436 | F5: 11 | G5: 70 | H5: usa | I5: plymouth satellite
A6: 16 | B6: 8 | C6: 304 | D6: 150 | E6: 3433 | F6: 12 | G6: 70 | H6: usa | I6: amc rebel sst
A7: 17 | B7: 8 | C7: 302 | D7: 140 | E7: 3449 | F7: 10.5 | G7: 70 | H7: usa | I7: ford torino
A8: 15 | B8: 8 | C8: 429 | D8: 198 | E8: 4341 | F8: 10 | G8: 70 | H8: usa | I8: ford galaxie 500
A9: 14 | B9: 8 | C9: 454 | D9: 220 | E9: 4354 | F9: 9 | G9: 70 | H9: usa | I9: chevrolet impala
A10: 14 | B10: 8 | C10: 440 | D10: 215 | E10: 4312 | F10: 8.5 | G10: 70 | H10: usa | I10: plymouth fury iii
A11: 14 | B11: 8 | C11: 455 | D11: 225 | E11: 4425 | F11: 10 | G11: 70 | H11: usa | I11: pontiac catalina
A12: 15 | B12: 8 | C12: 390 | D12: 190 | E12: 3850 | F12: 8.5 | G12: 70 | H12: usa | I12: amc ambassador dpl
A13: 15 | B13: 8 | C13: 383 | D13: 170 | E13: 3563 | F13: 10 | G13: 70 | H13: usa | I13: dodge challenger se
A14: 14 | B14: 8 | C14: 340 | D14: 160 | E14: 3609 | F14: 8 | G14: 70 | H14: usa | I14: plymouth 'cuda 340
... A400: 31 | B400: 4 | C400: 119 | D400: 82 | E400: 2720 | F400: 19.4 | G400: 82 | H400: usa | I400: chevy s-10

Sheet 1-Sample T-Test
A1: One-Sample T-Test — Is average MPG different from 25?
A3: Problem & Hypotheses
A4: We are given a sample of vehicles with an observed sample mean MPG. Determine whether the population mean MPG is significantly different from 25 at significance level α = 0.05. This is a two-tailed test.
A8: H0 (null): | B8: True average MPG = 25
A9: H1 (alternative): | B9: True average MPG ≠ 25
A11: Step 1 — Sample statistics
A12: Sample size (n) | B12: =COUNT(Data!$A$3:$A$400) -> 398
A13: Sample mean | B13: =AVERAGE(Data!$A$3:$A$400) -> 23.514573
A14: Sample std dev (s) | B14: =STDEV(Data!$A$3:$A$400) -> 7.8159843
A16: Step 2 — Hypothesised mean & test statistic
A17: Hypothesised mean (μ₀) | B17: 25
A18: Standard error (s / √n) | B18: =B14/SQRT(B12) -> 0.39177989
A19: t-statistic | B19: =(B13-B17)/B18 -> -3.7914838
A20: Degrees of freedom (n-1) | B20: =B12-1 -> 397
A22: Step 3 — p-value & decision
A23: p-value (two-tailed) | B23: =TDIST(ABS(B19),B20,2) -> 0.00017302334
A24: Significance level (α) | B24: 0.05
A26: Decision | B26: =IF(B23<B24,"Reject H0: Average MPG is significantly different from 25","Fail to reject H0: No significant difference from 25") -> Reject H0: Average MPG is significantly different from 25
A28: What the p-value means
A29: The p-value is the probability of observing a sample mean this far (or farther) from the hypothesised mean of 25, if the true population mean really were 25.
A32: Report
A33: =IF(B23<B24,"There is statistically significant evidence that the population mean MPG differs from 25 at the 5% level. "&IF(B19<0,"The negative t-statistic suggests the true mean MPG is likely below 25.","The positive t-statistic suggests the true mean MPG is likely above 25."),"There is not enough statistical evidence to conclude the population mean MPG differs from 25 at the 5% level.") -> There is statistically significant evidence that the population mean MPG differs from 25 at the 5% level. The negative t-statistic suggests the true mean MPG is likely below 25.

Sheet 2-Sample T-Test
A1: Two-Sample T-Test — USA vs Japan MPG
A3: Problem & Hypotheses
A4: Determine whether the average MPG differs between vehicles manufactured in the USA and Japan, at significance level α = 0.05 (two-tailed, independent samples). Sample sizes and variances differ between groups, so we use Welch's t-test (unequal variances).
A8: H0 (null): | B8: mean MPG (USA) = mean MPG (Japan)
A9: H1 (alternative): | B9: mean MPG (USA) ≠ mean MPG (Japan)
A11: Helper columns — pull each origin's MPG values
A12: Column F = MPG for USA rows only, Column G = MPG for Japan rows only (blank otherwise).
A13: Step 1 — Group statistics | F13: USA_mpg | G13: Japan_mpg
A14: n (USA) | B14: =COUNT(F14:F411) -> 249 | F14: =IF(Data!$H3="usa",Data!$A3,"") -> 18 | G14: =IF(Data!$H3="japan",Data!$A3,"")
A15: n (Japan) | B15: =COUNT(G14:G411) -> 79 | F15: =IF(Data!$H4="usa",Data!$A4,"") -> 15 | G15: =IF(Data!$H4="japan",Data!$A4,"")
A16: Mean MPG (USA) | B16: =AVERAGE(F14:F411) -> 20.083534 | F16: =IF(Data!$H5="usa",Data!$A5,"") -> 18 | G16: =IF(Data!$H5="japan",Data!$A5,"")
A17: Mean MPG (Japan) | B17: =AVERAGE(G14:G411) -> 30.450633 | F17: =IF(Data!$H6="usa",Data!$A6,"") -> 16 | G17: =IF(Data!$H6="japan",Data!$A6,"")
A18: Std dev (USA) | B18: =STDEV(F14:F411) -> 6.402892 | F18: =IF(Data!$H7="usa",Data!$A7,"") -> 17 | G18: =IF(Data!$H7="japan",Data!$A7,"")
A19: Std dev (Japan) | B19: =STDEV(G14:G411) -> 6.0900481 | F19: =IF(Data!$H8="usa",Data!$A8,"") -> 15 | G19: =IF(Data!$H8="japan",Data!$A8,"")
F20: =IF(Data!$H9="usa",Data!$A9,"") -> 14 | G20: =IF(Data!$H9="japan",Data!$A9,"")
A21: Step 2 — Welch's t-statistic & p-value | F21: =IF(Data!$H10="usa",Data!$A10,"") -> 14 | G21: =IF(Data!$H10="japan",Data!$A10,"")
A22: t-statistic (Welch) | B22: =(B16-B17)/SQRT((B18^2/B14)+(B19^2/B15)) -> -13.018778 | F22: =IF(Data!$H11="usa",Data!$A11,"") -> 14 | G22: =IF(Data!$H11="japan",Data!$A11,"")
A23: p-value (two-tailed, Welch) | B23: =TTEST(F14:F411,G14:G411,2,3) -> 1.0109535e-25 | C23: TTEST(range1, range2, tails, type) — type 3 = two-sample unequal variance (Welch) | F23: =IF(Data!$H12="usa",Data!$A12,"") -> 15 | G23: =IF(Data!$H12="japan",Data!$A12,"")
A24: Significance level (α) | B24: 0.05 | F24: =IF(Data!$H13="usa",Data!$A13,"") -> 15 | G24: =IF(Data!$H13="japan",Data!$A13,"")
F25: =IF(Data!$H14="usa",Data!$A14,"") -> 14 | G25: =IF(Data!$H14="japan",Data!$A14,"")
A26: Decision | B26: =IF(B23<B24,"Reject H0: The true average MPG of USA and Japan cars is not the same.","Fail to reject H0: The true average MPG of USA and Japan cars is not statistically different.") -> Reject H0: The true average MPG of USA and Japan cars is not the same. | F26: =IF(Data!$H15="usa",Data!$A15,"") -> 15 | G26: =IF(Data!$H15="japan",Data!$A15,"")
F27: =IF(Data!$H16="usa",Data!$A16,"") -> 14 | G27: =IF(Data!$H16="japan",Data!$A16,"")
A28: What the p-value means | F28: =IF(Data!$H17="usa",Data!$A17,"") | G28: =IF(Data!$H17="japan",Data!$A17,"") -> 24
A29: The p-value is the probability of observing a difference between the USA and Japan sample means at least this large, if the true population means were actually identical. | F29: =IF(Data!$H18="usa",Data!$A18,"") -> 22 | G29: =IF(Data!$H18="japan",Data!$A18,"")
F30: =IF(Data!$H19="usa",Data!$A19,"") -> 18 | G30: =IF(Data!$H19="japan",Data!$A19,"")
F31: =IF(Data!$H20="usa",Data!$A20,"") -> 21 | G31: =IF(Data!$H20="japan",Data!$A20,"")
A32: Report | F32: =IF(Data!$H21="usa",Data!$A21,"") | G32: =IF(Data!$H21="japan",Data!$A21,"") -> 27
A33: =IF(B23<B24,"A two-sample Welch's t-test found a statistically significant difference in mean MPG between USA and Japan (p < 0.05). "&IF(B17>B16,"Japanese cars have higher average MPG than US cars.","US cars have higher average MPG than Japanese cars."),"No statistically significant difference in mean MPG was found between USA and Japan cars at the 5% level.") -> A two-sample Welch's t-test found a statistically significant difference in mean MPG between USA and Japan (p < 0.05). Japanese cars have higher average MPG than US cars. | F33: =IF(Data!$H22="usa",Data!$A22,"") | G33: =IF(Data!$H22="japan",Data!$A22,"")
F34: =IF(Data!$H23="usa",Data!$A23,"") | G34: =IF(Data!$H23="japan",Data!$A23,"")
F35: =IF(Data!$H24="usa",Data!$A24,"") | G35: =IF(Data!$H24="japan",Data!$A24,"")
F36: =IF(Data!$H25="usa",Data!$A25,"") | G36: =IF(Data!$H25="japan",Data!$A25,"")
F37: =IF(Data!$H26="usa",Data!$A26,"") | G37: =IF(Data!$H26="japan",Data!$A26,"")
F38: =IF(Data!$H27="usa",Data!$A27,"") -> 21 | G38: =IF(Data!$H27="japan",Data!$A27,"")
F39: =IF(Data!$H28="usa",Data!$A28,"") -> 10 | G39: =IF(Data!$H28="japan",Data!$A28,"")
F40: =IF(Data!$H29="usa",Data!$A29,"") -> 10 | G40: =IF(Data!$H29="japan",Data!$A29,"")
F41: =IF(Data!$H30="usa",Data!$A30,"") -> 11 | G41: =IF(Data!$H30="japan",Data!$A30,"")
F42: =IF(Data!$H31="usa",Data!$A31,"") -> 9 | G42: =IF(Data!$H31="japan",Data!$A31,"")
F43: =IF(Data!$H32="usa",Data!$A32,"") | G43: =IF(Data!$H32="japan",Data!$A32,"") -> 27
F44: =IF(Data!$H33="usa",Data!$A33,"") -> 28 | G44: =IF(Data!$H33="japan",Data!$A33,"")
F45: =IF(Data!$H34="usa",Data!$A34,"") | G45: =IF(Data!$H34="japan",Data!$A34,"") -> 25
...

Sheet 1-Way ANOVA
A1: One-Way ANOVA — MPG across USA / Japan / Europe
A3: Problem & Hypotheses
A4: Is the difference in average MPG across USA, Japan, and Europe statistically significant, at significance level α = 0.05? A one-way ANOVA compares between-group variance to within-group variance.
A8: H0 (null): | B8: mean MPG (USA) = mean MPG (Japan) = mean MPG (Europe)
A9: H1 (alternative): | B9: At least one origin has a different mean MPG
A11: Helper columns — pull each origin's MPG values
A12: Column F = USA MPG, Column G = Japan MPG, Column H = Europe MPG (blank otherwise).
A13: Step 1 — Group means, std dev, counts | F13: USA_mpg | G13: Japan_mpg | H13: Europe_mpg
A14: n (USA) / n (Japan) / n (Europe) | B14: =COUNT(F14:F411) -> 249 | C14: =COUNT(G14:G411) -> 79 | D14: =COUNT(H14:H411) -> 70 | F14: =IF(Data!$H3="usa",Data!$A3,"") -> 18 | G14: =IF(Data!$H3="japan",Data!$A3,"") | H14: =IF(Data!$H3="europe",Data!$A3,"")
A15: Mean MPG (USA / Japan / Europe) | B15: =AVERAGE(F14:F411) -> 20.083534 | C15: =AVERAGE(G14:G411) -> 30.450633 | D15: =AVERAGE(H14:H411) -> 27.891429 | F15: =IF(Data!$H4="usa",Data!$A4,"") -> 15 | G15: =IF(Data!$H4="japan",Data!$A4,"") | H15: =IF(Data!$H4="europe",Data!$A4,"")
A16: Std dev (USA / Japan / Europe) | B16: =STDEV(F14:F411) -> 6.402892 | C16: =STDEV(G14:G411) -> 6.0900481 | D16: =STDEV(H14:H411) -> 6.7239296 | F16: =IF(Data!$H5="usa",Data!$A5,"") -> 18 | G16: =IF(Data!$H5="japan",Data!$A5,"") | H16: =IF(Data!$H5="europe",Data!$A5,"")
F17: =IF(Data!$H6="usa",Data!$A6,"") -> 16 | G17: =IF(Data!$H6="japan",Data!$A6,"") | H17: =IF(Data!$H6="europe",Data!$A6,"")
A18: Step 2 — Sum of squares (via DEVSQ) | F18: =IF(Data!$H7="usa",Data!$A7,"") -> 17 | G18: =IF(Data!$H7="japan",Data!$A7,"") | H18: =IF(Data!$H7="europe",Data!$A7,"")
A19: Total SS (all vehicles) | B19: =DEVSQ(Data!$A$3:$A$400) -> 24252.575 | F19: =IF(Data!$H8="usa",Data!$A8,"") -> 15 | G19: =IF(Data!$H8="japan",Data!$A8,"") | H19: =IF(Data!$H8="europe",Data!$A8,"")
A20: Within-group SS (sum of each group's SS) | B20: =DEVSQ(F14:F411)+DEVSQ(G14:G411)+DEVSQ(H14:H411) -> 16179.755 | F20: =IF(Data!$H9="usa",Data!$A9,"") -> 14 | G20: =IF(Data!$H9="japan",Data!$A9,"") | H20: =IF(Data!$H9="europe",Data!$A9,"")
A21: Between-group SS (Total − Within) | B21: =B19-B20 -> 8072.8207 | F21: =IF(Data!$H10="usa",Data!$A10,"") -> 14 | G21: =IF(Data!$H10="japan",Data!$A10,"") | H21: =IF(Data!$H10="europe",Data!$A10,"")
F22: =IF(Data!$H11="usa",Data!$A11,"") -> 14 | G22: =IF(Data!$H11="japan",Data!$A11,"") | H22: =IF(Data!$H11="europe",Data!$A11,"")
A23: Step 3 — F-statistic & p-value | F23: =IF(Data!$H12="usa",Data!$A12,"") -> 15 | G23: =IF(Data!$H12="japan",Data!$A12,"") | H23: =IF(Data!$H12="europe",Data!$A12,"")
A24: df between (k-1) | B24: =3-1 -> 2 | F24: =IF(Data!$H13="usa",Data!$A13,"") -> 15 | G24: =IF(Data!$H13="japan",Data!$A13,"") | H24: =IF(Data!$H13="europe",Data!$A13,"")
A25: df within (N-k) | B25: =COUNT(Data!$A$3:$A$400)-3 -> 395 | F25: =IF(Data!$H14="usa",Data!$A14,"") -> 14 | G25: =IF(Data!$H14="japan",Data!$A14,"") | H25: =IF(Data!$H14="europe",Data!$A14,"")
A26: MS between | B26: =B21/B24 -> 4036.4103 | F26: =IF(Data!$H15="usa",Data!$A15,"") -> 15 | G26: =IF(Data!$H15="japan",Data!$A15,"") | H26: =IF(Data!$H15="europe",Data!$A15,"")
A27: MS within | B27: =B20/B25 -> 40.961405 | F27: =IF(Data!$H16="usa",Data!$A16,"") -> 14 | G27: =IF(Data!$H16="japan",Data!$A16,"") | H27: =IF(Data!$H16="europe",Data!$A16,"")
A28: F-statistic | B28: =B26/B27 -> 98.541795 | F28: =IF(Data!$H17="usa",Data!$A17,"") | G28: =IF(Data!$H17="japan",Data!$A17,"") -> 24 | H28: =IF(Data!$H17="europe",Data!$A17,"")
A29: p-value | B29: =FDIST(B28,B24,B25) -> 1.9154864e-35 | C29: FDIST = right-tailed F-distribution p-value | F29: =IF(Data!$H18="usa",Data!$A18,"") -> 22 | G29: =IF(Data!$H18="japan",Data!$A18,"") | H29: =IF(Data!$H18="europe",Data!$A18,"")
A30: Significance level (α) | B30: 0.05 | F30: =IF(Data!$H19="usa",Data!$A19,"") -> 18 | G30: =IF(Data!$H19="japan",Data!$A19,"") | H30: =IF(Data!$H19="europe",Data!$A19,"")
F31: =IF(Data!$H20="usa",Data!$A20,"") -> 21 | G31: =IF(Data!$H20="japan",Data!$A20,"") | H31: =IF(Data!$H20="europe",Data!$A20,"")
A32: Decision | B32: =IF(B29<B30,"Reject H0: MPG differs significantly across origins","Fail to reject H0: No significant difference in MPG") -> Reject H0: MPG differs significantly across origins | F32: =IF(Data!$H21="usa",Data!$A21,"") | G32: =IF(Data!$H21="japan",Data!$A21,"") -> 27 | H32: =IF(Data!$H21="europe",Data!$A21,"")
F33: =IF(Data!$H22="usa",Data!$A22,"") | G33: =IF(Data!$H22="japan",Data!$A22,"") | H33: =IF(Data!$H22="europe",Data!$A22,"") -> 26
A34: What the p-value means | F34: =IF(Data!$H23="usa",Data!$A23,"") | G34: =IF(Data!$H23="japan",Data!$A23,"") | H34: =IF(Data!$H23="europe",Data!$A23,"") -> 25
A35: The p-value is the probability of observing group mean differences at least this large if the true means for USA, Japan, and Europe were actually identical. | F35: =IF(Data!$H24="usa",Data!$A24,"") | G35: =IF(Data!$H24="japan",Data!$A24,"") | H35: =IF(Data!$H24="europe",Data!$A24,"") -> 24
F36: =IF(Data!$H25="usa",Data!$A25,"") | G36: =IF(Data!$H25="japan",Data!$A25,"") | H36: =IF(Data!$H25="europe",Data!$A25,"") -> 25
F37: =IF(Data!$H26="usa",Data!$A26,"") | G37: =IF(Data!$H26="japan",Data!$A26,"") | H37: =IF(Data!$H26="europe",Data!$A26,"") -> 26
A38: Report | F38: =IF(Data!$H27="usa",Data!$A27,"") -> 21 | G38: =IF(Data!$H27="japan",Data!$A27,"") | H38: =IF(Data!$H27="europe",Data!$A27,"")
A39: =IF(B29<B30,"Average MPG differs significantly across USA, Japan, and Europe based cars. This means the variation in fuel efficiency between these regions is statistically significant and unlikely to be due to chance.","No statistically significant difference in average MPG was found across USA, Japan, and Europe.") -> Average MPG differs significantly across USA, Japan, and Europe based cars. This means the variation in fuel efficiency between these regions is statistically significant and unlikely to be due to chance. | F39: =IF(Data!$H28="usa",Data!$A28,"") -> 10 | G39: =IF(Data!$H28="japan",Data!$A28,"") | H39: =IF(Data!$H28="europe",Data!$A28,"")
F40: =IF(Data!$H29="usa",Data!$A29,"") -> 10 | G40: =IF(Data!$H29="japan",Data!$A29,"") | H40: =IF(Data!$H29="europe",Data!$A29,"")
F41: =IF(Data!$H30="usa",Data!$A30,"") -> 11 | G41: =IF(Data!$H30="japan",Data!$A30,"") | H41: =IF(Data!$H30="europe",Data!$A30,"")
F42: =IF(Data!$H31="usa",Data!$A31,"") -> 9 | G42: =IF(Data!$H31="japan",Data!$A31,"") | H42: =IF(Data!$H31="europe",Data!$A31,"")
F43: =IF(Data!$H32="usa",Data!$A32,"") | G43: =IF(Data!$H32="japan",Data!$A32,"") -> 27 | H43: =IF(Data!$H32="europe",Data!$A32,"")
F44: =IF(Data!$H33="usa",Data!$A33,"") -> 28 | G44: =IF(Data!$H33="japan",Data!$A33,"") | H44: =IF(Data!$H33="europe",Data!$A33,"")
F45: =IF(Data!$H34="usa",Data!$A34,"") | G45: =IF(Data!$H34="japan",Data!$A34,"") -> 25 | H45: =IF(Data!$H34="europe",Data!$A34,"")
...

Sheet Correlation
A1: Correlation Significance Test — Weight vs MPG
A3: Problem & Hypotheses
A4: Is the relationship between weight and MPG statistically significant, at significance level α = 0.05? We test whether the observed correlation reflects a real population-level association, using a Pearson correlation significance test.
A8: H0 (null): | B8: ρ = 0 (no correlation)
A9: H1 (alternative): | B9: ρ ≠ 0 (there is correlation)
A11: Step 1 — Correlation coefficient
A12: n | B12: =COUNT(Data!$A$3:$A$400) -> 398
A13: Correlation (r) | B13: =CORREL(Data!$E$3:$E$400,Data!$A$3:$A$400) -> -0.83174093
A15: Step 2 — t-statistic & p-value
A16: t-statistic (r·√(n-2) / √(1-r²)) | B16: =B13*SQRT(B12-2)/SQRT(1-B13^2) -> -29.813599
A17: Degrees of freedom (n-2) | B17: =B12-2 -> 396
A18: p-value (two-tailed) | B18: =TDIST(ABS(B16),B17,2) -> 2.9727996e-103
A19: Significance level (α) | B19: 0.05
A21: Decision | B21: =IF(B18<B19,"Reject H0: There is correlation","Fail to reject H0: No significant correlation") -> Reject H0: There is correlation
A23: What the p-value means
A24: The p-value is the probability of observing a correlation this far from zero in a sample, if there were actually no relationship between weight and MPG in the population.
A27: Report
A28: =IF(B18<B19,"There is strong statistical evidence of a statistically significant linear relationship between weight and MPG. "&IF(B13<0,"As weight increases, MPG decreases on average (heavier cars tend to be less fuel efficient).","As weight increases, MPG increases on average."),"No statistically significant linear relationship was found between weight and MPG.") -> There is strong statistical evidence of a statistically significant linear relationship between weight and MPG. As weight increases, MPG decreases on average (heavier cars tend to be less fuel efficient).

Sheet Variance Test
A1: Variance Test — USA vs Japan MPG variance
A3: Problem & Hypotheses
A4: Is there a statistically significant difference in MPG variance between USA and Japan cars, at significance level α = 0.05? The notebook used Levene's test (robust to non-normality); Excel's built-in equivalent is the F-test for equality of two variances (FTEST), which is the classic parametric analogue and gives the same practical conclusion here.
A9: H0 (null): | B9: Var(MPG, USA) = Var(MPG, Japan)
A10: H1 (alternative): | B10: Variances are different
A12: Helper columns — pull each origin's MPG values
A13: Column F = MPG for USA rows only, Column G = MPG for Japan rows only.
A14: Step 1 — Variance by group | F14: USA_mpg | G14: Japan_mpg
A15: Variance (USA) | B15: =VAR(F15:F412) -> 40.997026 | F15: =IF(Data!$H3="usa",Data!$A3,"") -> 18 | G15: =IF(Data!$H3="japan",Data!$A3,"")
A16: Variance (Japan) | B16: =VAR(G15:G412) -> 37.088685 | F16: =IF(Data!$H4="usa",Data!$A4,"") -> 15 | G16: =IF(Data!$H4="japan",Data!$A4,"")
F17: =IF(Data!$H5="usa",Data!$A5,"") -> 18 | G17: =IF(Data!$H5="japan",Data!$A5,"")
A18: Step 2 — F-test for equality of variances | F18: =IF(Data!$H6="usa",Data!$A6,"") -> 16 | G18: =IF(Data!$H6="japan",Data!$A6,"")
A19: F ratio (larger var / smaller var) | B19: =MAX(B15,B16)/MIN(B15,B16) -> 1.1053782 | F19: =IF(Data!$H7="usa",Data!$A7,"") -> 17 | G19: =IF(Data!$H7="japan",Data!$A7,"")
A20: p-value (two-tailed F-test) | B20: =FTEST(F15:F412,G15:G412) -> 0.61144663 | F20: =IF(Data!$H8="usa",Data!$A8,"") -> 15 | G20: =IF(Data!$H8="japan",Data!$A8,"")
A21: Significance level (α) | B21: 0.05 | F21: =IF(Data!$H9="usa",Data!$A9,"") -> 14 | G21: =IF(Data!$H9="japan",Data!$A9,"")
F22: =IF(Data!$H10="usa",Data!$A10,"") -> 14 | G22: =IF(Data!$H10="japan",Data!$A10,"")
A23: Decision | B23: =IF(B20<B21,"Reject H0: Variances are not equal","Fail to reject H0: Not enough evidence to reject H0") -> Fail to reject H0: Not enough evidence to reject H0 | F23: =IF(Data!$H11="usa",Data!$A11,"") -> 14 | G23: =IF(Data!$H11="japan",Data!$A11,"")
F24: =IF(Data!$H12="usa",Data!$A12,"") -> 15 | G24: =IF(Data!$H12="japan",Data!$A12,"")
A25: What the p-value means | F25: =IF(Data!$H13="usa",Data!$A13,"") -> 15 | G25: =IF(Data!$H13="japan",Data!$A13,"")
A26: The p-value is the probability of observing a variance ratio this different between USA and Japan cars if the true population variances were actually identical. | F26: =IF(Data!$H14="usa",Data!$A14,"") -> 14 | G26: =IF(Data!$H14="japan",Data!$A14,"")
F27: =IF(Data!$H15="usa",Data!$A15,"") -> 15 | G27: =IF(Data!$H15="japan",Data!$A15,"")
F28: =IF(Data!$H16="usa",Data!$A16,"") -> 14 | G28: =IF(Data!$H16="japan",Data!$A16,"")
A29: Report | F29: =IF(Data!$H17="usa",Data!$A17,"") | G29: =IF(Data!$H17="japan",Data!$A17,"") -> 24
A30: =IF(B20<B21,"There is statistically significant evidence that the MPG variance differs between USA and Japan cars.","There is no statistically significant evidence that the MPG variance differs between USA and Japan cars. Their MPG variability appears statistically similar, even though their mean MPG values are quite different.") -> There is no statistically significant evidence that the MPG variance differs between USA and Japan cars. Their MPG variability appears statistically similar, even though their mean MPG values are quite different. | F30: =IF(Data!$H18="usa",Data!$A18,"") -> 22 | G30: =IF(Data!$H18="japan",Data!$A18,"")
F31: =IF(Data!$H19="usa",Data!$A19,"") -> 18 | G31: =IF(Data!$H19="japan",Data!$A19,"")
F32: =IF(Data!$H20="usa",Data!$A20,"") -> 21 | G32: =IF(Data!$H20="japan",Data!$A20,"")
F33: =IF(Data!$H21="usa",Data!$A21,"") | G33: =IF(Data!$H21="japan",Data!$A21,"") -> 27
F34: =IF(Data!$H22="usa",Data!$A22,"") | G34: =IF(Data!$H22="japan",Data!$A22,"")
F35: =IF(Data!$H23="usa",Data!$A23,"") | G35: =IF(Data!$H23="japan",Data!$A23,"")
F36: =IF(Data!$H24="usa",Data!$A24,"") | G36: =IF(Data!$H24="japan",Data!$A24,"")
F37: =IF(Data!$H25="usa",Data!$A25,"") | G37: =IF(Data!$H25="japan",Data!$A25,"")
F38: =IF(Data!$H26="usa",Data!$A26,"") | G38: =IF(Data!$H26="japan",Data!$A26,"")
F39: =IF(Data!$H27="usa",Data!$A27,"") -> 21 | G39: =IF(Data!$H27="japan",Data!$A27,"")
F40: =IF(Data!$H28="usa",Data!$A28,"") -> 10 | G40: =IF(Data!$H28="japan",Data!$A28,"")
F41: =IF(Data!$H29="usa",Data!$A29,"") -> 10 | G41: =IF(Data!$H29="japan",Data!$A29,"")
F42: =IF(Data!$H30="usa",Data!$A30,"") -> 11 | G42: =IF(Data!$H30="japan",Data!$A30,"")
... F412: =IF(Data!$H400="usa",Data!$A400,"") -> 31 | G412: =IF(Data!$H400="japan",Data!$A400,"")

Sheet Newer vs Older
A1: One-Sided T-Test — Are newer cars (post-1975) more efficient?
A3: Problem & Hypotheses
A4: Compare average MPG for cars from model years 1976+ ('newer') vs 1975 and earlier ('older'), at significance level α = 0.05. This is a one-sided Welch's t-test.
A8: H0 (null): | B8: Newer and older cars have the same mean MPG
A9: H1 (alternative): | B9: Newer cars have higher mean MPG than older cars
A11: Helper columns — split MPG by era
A12: Column F = MPG for model_year ≤ 75 ('older'), Column G = MPG for model_year > 75 ('newer').
A13: Step 1 — Group statistics | F13: Older_mpg | G13: Newer_mpg
A14: n (older) / n (newer) | B14: =COUNT(F14:F411) -> 182 | C14: =COUNT(G14:G411) -> 216 | F14: =IF(Data!$G3<=75,Data!$A3,"") -> 18 | G14: =IF(Data!$G3>75,Data!$A3,"")
A15: Mean MPG (older) | B15: =AVERAGE(F14:F411) -> 19.434066 | F15: =IF(Data!$G4<=75,Data!$A4,"") -> 15 | G15: =IF(Data!$G4>75,Data!$A4,"")
A16: Mean MPG (newer) | B16: =AVERAGE(G14:G411) -> 26.952778 | F16: =IF(Data!$G5<=75,Data!$A5,"") -> 18 | G16: =IF(Data!$G5>75,Data!$A5,"")
F17: =IF(Data!$G6<=75,Data!$A6,"") -> 16 | G17: =IF(Data!$G6>75,Data!$A6,"")
A18: Step 2 — One-sided Welch's t-test | F18: =IF(Data!$G7<=75,Data!$A7,"") -> 17 | G18: =IF(Data!$G7>75,Data!$A7,"")
A19: p-value (one-tailed, newer > older) | B19: =TTEST(G14:G411,F14:F411,1,3) -> 1.6705651e-25 | C19: TTEST(array1, array2, tails=1, type=3) — one-tailed, unequal variance (Welch) | F19: =IF(Data!$G8<=75,Data!$A8,"") -> 15 | G19: =IF(Data!$G8>75,Data!$A8,"")
A20: Significance level (α) | B20: 0.05 | F20: =IF(Data!$G9<=75,Data!$A9,"") -> 14 | G20: =IF(Data!$G9>75,Data!$A9,"")
F21: =IF(Data!$G10<=75,Data!$A10,"") -> 14 | G21: =IF(Data!$G10>75,Data!$A10,"")
A22: Decision | B22: =IF(B19<B20,"Reject H0: Newer cars have significantly higher mean MPG than older cars","Fail to reject H0: Not enough evidence that newer cars have higher mean MPG") -> Reject H0: Newer cars have significantly higher mean MPG than older cars | F22: =IF(Data!$G11<=75,Data!$A11,"") -> 14 | G22: =IF(Data!$G11>75,Data!$A11,"")
F23: =IF(Data!$G12<=75,Data!$A12,"") -> 15 | G23: =IF(Data!$G12>75,Data!$A12,"")
A24: What the p-value means | F24: =IF(Data!$G13<=75,Data!$A13,"") -> 15 | G24: =IF(Data!$G13>75,Data!$A13,"")
A25: The p-value is the probability of observing newer cars with a mean MPG this much higher than older cars, if newer and older cars actually had the same true mean MPG. | F25: =IF(Data!$G14<=75,Data!$A14,"") -> 14 | G25: =IF(Data!$G14>75,Data!$A14,"")
F26: =IF(Data!$G15<=75,Data!$A15,"") -> 15 | G26: =IF(Data!$G15>75,Data!$A15,"")
F27: =IF(Data!$G16<=75,Data!$A16,"") -> 14 | G27: =IF(Data!$G16>75,Data!$A16,"")
A28: Report | F28: =IF(Data!$G17<=75,Data!$A17,"") -> 24 | G28: =IF(Data!$G17>75,Data!$A17,"")
A29: =IF(B19<B20,"There is very strong statistical evidence that newer cars (after 1975) are more fuel-efficient (higher MPG) than older cars (1975 and earlier) in this dataset.","There is not enough statistical evidence to conclude that newer cars have higher MPG than older cars.") -> There is very strong statistical evidence that newer cars (after 1975) are more fuel-efficient (higher MPG) than older cars (1975 and earlier) in this dataset. | F29: =IF(Data!$G18<=75,Data!$A18,"") -> 22 | G29: =IF(Data!$G18>75,Data!$A18,"")
F30: =IF(Data!$G19<=75,Data!$A19,"") -> 18 | G30: =IF(Data!$G19>75,Data!$A19,"")
F31: =IF(Data!$G20<=75,Data!$A20,"") -> 21 | G31: =IF(Data!$G20>75,Data!$A20,"")
F32: =IF(Data!$G21<=75,Data!$A21,"") -> 27 | G32: =IF(Data!$G21>75,Data!$A21,"")
F33: =IF(Data!$G22<=75,Data!$A22,"") -> 26 | G33: =IF(Data!$G22>75,Data!$A22,"")
F34: =IF(Data!$G23<=75,Data!$A23,"") -> 25 | G34: =IF(Data!$G23>75,Data!$A23,"")
F35: =IF(Data!$G24<=75,Data!$A24,"") -> 24 | G35: =IF(Data!$G24>75,Data!$A24,"")
F36: =IF(Data!$G25<=75,Data!$A25,"") -> 25 | G36: =IF(Data!$G25>75,Data!$A25,"")
F37: =IF(Data!$G26<=75,Data!$A26,"") -> 26 | G37: =IF(Data!$G26>75,Data!$A26,"")
F38: =IF(Data!$G27<=75,Data!$A27,"") -> 21 | G38: =IF(Data!$G27>75,Data!$A27,"")
F39: =IF(Data!$G28<=75,Data!$A28,"") -> 10 | G39: =IF(Data!$G28>75,Data!$A28,"")
F40: =IF(Data!$G29<=75,Data!$A29,"") -> 10 | G40: =IF(Data!$G29>75,Data!$A29,"")
F41: =IF(Data!$G30<=75,Data!$A30,"") -> 11 | G41: =IF(Data!$G30>75,Data!$A30,"")
... F411: =IF(Data!$G400<=75,Data!$A400,"") | G411: =IF(Data!$G400>75,Data!$A400,"") -> 31
